<?xml version="1.0"?>
<sdf version="1.10">
  <model name="level_vehicle">
    <pose>0 0 0 0 0 0</pose>

    <link name="chassis">
      <pose>0 0 0.45 0 0 0</pose>
      <inertial>
        <mass>2.0</mass>
        <inertia>
          <ixx>0.25</ixx>
          <iyy>0.35</iyy>
          <izz>0.45</izz>
        </inertia>
      </inertial>
      <visual name="visual">
        <geometry>
          <box>
            <size>1.2 0.7 0.35</size>
          </box>
        </geometry>
        <material>
          <ambient>1.0 0.85 0.15 1</ambient>
          <diffuse>1.0 0.85 0.15 1</diffuse>
          <specular>0.2 0.2 0.1 1</specular>
        </material>
      </visual>
      <collision name="collision">
        <geometry>
          <box>
            <size>1.2 0.7 0.35</size>
          </box>
        </geometry>
      </collision>
    </link>

    <link name="left_wheel">
      <pose>0 0.45 0.25 -1.5707 0 0</pose>
      <inertial>
        <mass>0.4</mass>
        <inertia>
          <ixx>0.01</ixx>
          <iyy>0.01</iyy>
          <izz>0.01</izz>
        </inertia>
      </inertial>
      <visual name="visual">
        <geometry>
          <cylinder>
            <radius>0.25</radius>
            <length>0.16</length>
          </cylinder>
        </geometry>
        <material>
          <ambient>0.05 0.05 0.05 1</ambient>
          <diffuse>0.05 0.05 0.05 1</diffuse>
        </material>
      </visual>
      <collision name="collision">
        <geometry>
          <cylinder>
            <radius>0.25</radius>
            <length>0.16</length>
          </cylinder>
        </geometry>
      </collision>
    </link>

    <link name="right_wheel">
      <pose>0 -0.45 0.25 -1.5707 0 0</pose>
      <inertial>
        <mass>0.4</mass>
        <inertia>
          <ixx>0.01</ixx>
          <iyy>0.01</iyy>
          <izz>0.01</izz>
        </inertia>
      </inertial>
      <visual name="visual">
        <geometry>
          <cylinder>
            <radius>0.25</radius>
            <length>0.16</length>
          </cylinder>
        </geometry>
        <material>
          <ambient>0.05 0.05 0.05 1</ambient>
          <diffuse>0.05 0.05 0.05 1</diffuse>
        </material>
      </visual>
      <collision name="collision">
        <geometry>
          <cylinder>
            <radius>0.25</radius>
            <length>0.16</length>
          </cylinder>
        </geometry>
      </collision>
    </link>

    <joint name="left_wheel_joint" type="revolute">
      <parent>chassis</parent>
      <child>left_wheel</child>
      <axis>
        <xyz>0 0 1</xyz>
      </axis>
    </joint>

    <joint name="right_wheel_joint" type="revolute">
      <parent>chassis</parent>
      <child>right_wheel</child>
      <axis>
        <xyz>0 0 1</xyz>
      </axis>
    </joint>

    <plugin filename="gz-sim-diff-drive-system" name="gz::sim::systems::DiffDrive">
      <left_joint>left_wheel_joint</left_joint>
      <right_joint>right_wheel_joint</right_joint>
      <wheel_separation>0.9</wheel_separation>
      <wheel_radius>0.25</wheel_radius>
      <topic>/model/level_vehicle/cmd_vel</topic>
    </plugin>
  </model>
</sdf>
